[2018-06-11 12:21:18,741] {/home/rancard009/.local/lib/python3.6/site-packages/flask/app.py:1761} ERROR - Exception on /config [POST]
Traceback (most recent call last):
  File "/home/rancard009/.local/lib/python3.6/site-packages/flask/app.py", line 2292, in wsgi_app
    response = self.full_dispatch_request()
  File "/home/rancard009/.local/lib/python3.6/site-packages/flask/app.py", line 1815, in full_dispatch_request
    rv = self.handle_user_exception(e)
  File "/home/rancard009/.local/lib/python3.6/site-packages/flask/app.py", line 1718, in handle_user_exception
    reraise(exc_type, exc_value, tb)
  File "/home/rancard009/.local/lib/python3.6/site-packages/flask/_compat.py", line 35, in reraise
    raise value
  File "/home/rancard009/.local/lib/python3.6/site-packages/flask/app.py", line 1813, in full_dispatch_request
    rv = self.dispatch_request()
  File "/home/rancard009/.local/lib/python3.6/site-packages/flask/app.py", line 1799, in dispatch_request
    return self.view_functions[rule.endpoint](**req.view_args)
  File "/home/rancard009/Development/flask/flaskdev.py", line 42, in getAndCreatedConfig
    config = Config(config_resUrl, config_name, config_category, datetime.now())
NameError: name 'Config' is not defined
[2018-06-11 12:22:32,867] {/home/rancard009/.local/lib/python3.6/site-packages/flask/app.py:1761} ERROR - Exception on /config [POST]
Traceback (most recent call last):
  File "/home/rancard009/.local/lib/python3.6/site-packages/flask/app.py", line 2292, in wsgi_app
    response = self.full_dispatch_request()
  File "/home/rancard009/.local/lib/python3.6/site-packages/flask/app.py", line 1815, in full_dispatch_request
    rv = self.handle_user_exception(e)
  File "/home/rancard009/.local/lib/python3.6/site-packages/flask/app.py", line 1718, in handle_user_exception
    reraise(exc_type, exc_value, tb)
  File "/home/rancard009/.local/lib/python3.6/site-packages/flask/_compat.py", line 35, in reraise
    raise value
  File "/home/rancard009/.local/lib/python3.6/site-packages/flask/app.py", line 1813, in full_dispatch_request
    rv = self.dispatch_request()
  File "/home/rancard009/.local/lib/python3.6/site-packages/flask/app.py", line 1799, in dispatch_request
    return self.view_functions[rule.endpoint](**req.view_args)
  File "/home/rancard009/Development/flask/flaskdev.py", line 42, in getAndCreatedConfig
    config_category = request.args.get('categoryId')
NameError: name 'Config' is not defined
[2018-06-11 12:24:52,992] {/home/rancard009/.local/lib/python3.6/site-packages/flask/app.py:1761} ERROR - Exception on /config [POST]
Traceback (most recent call last):
  File "/home/rancard009/.local/lib/python3.6/site-packages/flask/app.py", line 2292, in wsgi_app
    response = self.full_dispatch_request()
  File "/home/rancard009/.local/lib/python3.6/site-packages/flask/app.py", line 1815, in full_dispatch_request
    rv = self.handle_user_exception(e)
  File "/home/rancard009/.local/lib/python3.6/site-packages/flask/app.py", line 1718, in handle_user_exception
    reraise(exc_type, exc_value, tb)
  File "/home/rancard009/.local/lib/python3.6/site-packages/flask/_compat.py", line 35, in reraise
    raise value
  File "/home/rancard009/.local/lib/python3.6/site-packages/flask/app.py", line 1813, in full_dispatch_request
    rv = self.dispatch_request()
  File "/home/rancard009/.local/lib/python3.6/site-packages/flask/app.py", line 1799, in dispatch_request
    return self.view_functions[rule.endpoint](**req.view_args)
  File "/home/rancard009/Development/flask/flaskdev.py", line 43, in getAndCreatedConfig
    config = Config(config_resUrl, config_name, config_category, datetime.now())
TypeError: __init__() missing 1 required positional argument: 'createdOn'
[2018-06-11 12:29:05,571] {/home/rancard009/.local/lib/python3.6/site-packages/flask/app.py:1761} ERROR - Exception on /config [POST]
Traceback (most recent call last):
  File "/home/rancard009/.local/lib/python3.6/site-packages/flask/app.py", line 2292, in wsgi_app
    response = self.full_dispatch_request()
  File "/home/rancard009/.local/lib/python3.6/site-packages/flask/app.py", line 1815, in full_dispatch_request
    rv = self.handle_user_exception(e)
  File "/home/rancard009/.local/lib/python3.6/site-packages/flask/app.py", line 1718, in handle_user_exception
    reraise(exc_type, exc_value, tb)
  File "/home/rancard009/.local/lib/python3.6/site-packages/flask/_compat.py", line 35, in reraise
    raise value
  File "/home/rancard009/.local/lib/python3.6/site-packages/flask/app.py", line 1813, in full_dispatch_request
    rv = self.dispatch_request()
  File "/home/rancard009/.local/lib/python3.6/site-packages/flask/app.py", line 1799, in dispatch_request
    return self.view_functions[rule.endpoint](**req.view_args)
  File "/home/rancard009/Development/flask/flaskdev.py", line 44, in getAndCreatedConfig
    config_data = config.save()
  File "/home/rancard009/Development/flask/Config.py", line 10, in save
    config = none
NameError: name 'none' is not defined
[2018-06-11 12:29:58,625] {/home/rancard009/.local/lib/python3.6/site-packages/flask/app.py:1761} ERROR - Exception on /config [POST]
Traceback (most recent call last):
  File "/home/rancard009/.local/lib/python3.6/site-packages/flask/app.py", line 2292, in wsgi_app
    response = self.full_dispatch_request()
  File "/home/rancard009/.local/lib/python3.6/site-packages/flask/app.py", line 1815, in full_dispatch_request
    rv = self.handle_user_exception(e)
  File "/home/rancard009/.local/lib/python3.6/site-packages/flask/app.py", line 1718, in handle_user_exception
    reraise(exc_type, exc_value, tb)
  File "/home/rancard009/.local/lib/python3.6/site-packages/flask/_compat.py", line 35, in reraise
    raise value
  File "/home/rancard009/.local/lib/python3.6/site-packages/flask/app.py", line 1813, in full_dispatch_request
    rv = self.dispatch_request()
  File "/home/rancard009/.local/lib/python3.6/site-packages/flask/app.py", line 1799, in dispatch_request
    return self.view_functions[rule.endpoint](**req.view_args)
  File "/home/rancard009/Development/flask/flaskdev.py", line 44, in getAndCreatedConfig
    config_data = config.save()
  File "/home/rancard009/Development/flask/Config.py", line 11, in save
    category = Category()
NameError: name 'Category' is not defined
[2018-06-11 12:30:41,348] {/home/rancard009/.local/lib/python3.6/site-packages/flask/app.py:1761} ERROR - Exception on /config [POST]
Traceback (most recent call last):
  File "/home/rancard009/Development/flask/Config.py", line 15, in save
    con = pymysql.connect('localhost','root', 'rancard', 'data_curation')
NameError: name 'pymysql' is not defined

During handling of the above exception, another exception occurred:

Traceback (most recent call last):
  File "/home/rancard009/Development/flask/Config.py", line 28, in save
    db.rollback()
NameError: name 'db' is not defined

During handling of the above exception, another exception occurred:

Traceback (most recent call last):
  File "/home/rancard009/.local/lib/python3.6/site-packages/flask/app.py", line 2292, in wsgi_app
    response = self.full_dispatch_request()
  File "/home/rancard009/.local/lib/python3.6/site-packages/flask/app.py", line 1815, in full_dispatch_request
    rv = self.handle_user_exception(e)
  File "/home/rancard009/.local/lib/python3.6/site-packages/flask/app.py", line 1718, in handle_user_exception
    reraise(exc_type, exc_value, tb)
  File "/home/rancard009/.local/lib/python3.6/site-packages/flask/_compat.py", line 35, in reraise
    raise value
  File "/home/rancard009/.local/lib/python3.6/site-packages/flask/app.py", line 1813, in full_dispatch_request
    rv = self.dispatch_request()
  File "/home/rancard009/.local/lib/python3.6/site-packages/flask/app.py", line 1799, in dispatch_request
    return self.view_functions[rule.endpoint](**req.view_args)
  File "/home/rancard009/Development/flask/flaskdev.py", line 44, in getAndCreatedConfig
    config_data = config.save()
  File "/home/rancard009/Development/flask/Config.py", line 31, in save
    if con != None:
UnboundLocalError: local variable 'con' referenced before assignment
[2018-06-11 12:31:36,896] {/home/rancard009/.local/lib/python3.6/site-packages/flask/app.py:1761} ERROR - Exception on /config [POST]
Traceback (most recent call last):
  File "/home/rancard009/Development/flask/Config.py", line 16, in save
    con = pymysql.connect('localhost','root', 'rancard', 'data_curation')
NameError: name 'pymysql' is not defined

During handling of the above exception, another exception occurred:

Traceback (most recent call last):
  File "/home/rancard009/.local/lib/python3.6/site-packages/flask/app.py", line 2292, in wsgi_app
    response = self.full_dispatch_request()
  File "/home/rancard009/.local/lib/python3.6/site-packages/flask/app.py", line 1815, in full_dispatch_request
    rv = self.handle_user_exception(e)
  File "/home/rancard009/.local/lib/python3.6/site-packages/flask/app.py", line 1718, in handle_user_exception
    reraise(exc_type, exc_value, tb)
  File "/home/rancard009/.local/lib/python3.6/site-packages/flask/_compat.py", line 35, in reraise
    raise value
  File "/home/rancard009/.local/lib/python3.6/site-packages/flask/app.py", line 1813, in full_dispatch_request
    rv = self.dispatch_request()
  File "/home/rancard009/.local/lib/python3.6/site-packages/flask/app.py", line 1799, in dispatch_request
    return self.view_functions[rule.endpoint](**req.view_args)
  File "/home/rancard009/Development/flask/flaskdev.py", line 44, in getAndCreatedConfig
    config_data = config.save()
  File "/home/rancard009/Development/flask/Config.py", line 29, in save
    db.rollback()
NameError: name 'db' is not defined
[2018-06-11 12:32:29,193] {/home/rancard009/.local/lib/python3.6/site-packages/flask/app.py:1761} ERROR - Exception on /config [POST]
Traceback (most recent call last):
  File "/home/rancard009/Development/flask/Config.py", line 16, in save
    con = pymysql.connect('localhost','root', 'rancard', 'data_curation')
NameError: name 'pymysql' is not defined

During handling of the above exception, another exception occurred:

Traceback (most recent call last):
  File "/home/rancard009/.local/lib/python3.6/site-packages/flask/app.py", line 2292, in wsgi_app
    response = self.full_dispatch_request()
  File "/home/rancard009/.local/lib/python3.6/site-packages/flask/app.py", line 1815, in full_dispatch_request
    rv = self.handle_user_exception(e)
  File "/home/rancard009/.local/lib/python3.6/site-packages/flask/app.py", line 1718, in handle_user_exception
    reraise(exc_type, exc_value, tb)
  File "/home/rancard009/.local/lib/python3.6/site-packages/flask/_compat.py", line 35, in reraise
    raise value
  File "/home/rancard009/.local/lib/python3.6/site-packages/flask/app.py", line 1813, in full_dispatch_request
    rv = self.dispatch_request()
  File "/home/rancard009/.local/lib/python3.6/site-packages/flask/app.py", line 1799, in dispatch_request
    return self.view_functions[rule.endpoint](**req.view_args)
  File "/home/rancard009/Development/flask/flaskdev.py", line 44, in getAndCreatedConfig
    config_data = config.save()
  File "/home/rancard009/Development/flask/Config.py", line 29, in save
    con.rollback()
AttributeError: 'NoneType' object has no attribute 'rollback'
[2018-06-11 12:41:45,593] {/home/rancard009/.local/lib/python3.6/site-packages/flask/app.py:1761} ERROR - Exception on /config [POST]
Traceback (most recent call last):
  File "/home/rancard009/.local/lib/python3.6/site-packages/flask/app.py", line 2292, in wsgi_app
    response = self.full_dispatch_request()
  File "/home/rancard009/.local/lib/python3.6/site-packages/flask/app.py", line 1815, in full_dispatch_request
    rv = self.handle_user_exception(e)
  File "/home/rancard009/.local/lib/python3.6/site-packages/flask/app.py", line 1718, in handle_user_exception
    reraise(exc_type, exc_value, tb)
  File "/home/rancard009/.local/lib/python3.6/site-packages/flask/_compat.py", line 35, in reraise
    raise value
  File "/home/rancard009/.local/lib/python3.6/site-packages/flask/app.py", line 1813, in full_dispatch_request
    rv = self.dispatch_request()
  File "/home/rancard009/.local/lib/python3.6/site-packages/flask/app.py", line 1799, in dispatch_request
    return self.view_functions[rule.endpoint](**req.view_args)
  File "/home/rancard009/Development/flask/flaskdev.py", line 48, in getAndCreatedConfig
    jsonData = json.dumps(data)
  File "/usr/lib/python3.6/json/__init__.py", line 231, in dumps
    return _default_encoder.encode(obj)
  File "/usr/lib/python3.6/json/encoder.py", line 199, in encode
    chunks = self.iterencode(o, _one_shot=True)
  File "/usr/lib/python3.6/json/encoder.py", line 257, in iterencode
    return _iterencode(o, 0)
  File "/usr/lib/python3.6/json/encoder.py", line 180, in default
    o.__class__.__name__)
TypeError: Object of type 'datetime' is not JSON serializable
[2018-06-11 20:37:32,570] {/home/rancard009/.local/lib/python3.6/site-packages/flask/app.py:1761} ERROR - Exception on /favicon.ico [GET]
Traceback (most recent call last):
  File "/home/rancard009/.local/lib/python3.6/site-packages/flask/app.py", line 2292, in wsgi_app
    response = self.full_dispatch_request()
  File "/home/rancard009/.local/lib/python3.6/site-packages/flask/app.py", line 1815, in full_dispatch_request
    rv = self.handle_user_exception(e)
  File "/home/rancard009/.local/lib/python3.6/site-packages/flask/app.py", line 1718, in handle_user_exception
    reraise(exc_type, exc_value, tb)
  File "/home/rancard009/.local/lib/python3.6/site-packages/flask/_compat.py", line 35, in reraise
    raise value
  File "/home/rancard009/.local/lib/python3.6/site-packages/flask/app.py", line 1813, in full_dispatch_request
    rv = self.dispatch_request()
  File "/home/rancard009/.local/lib/python3.6/site-packages/flask/app.py", line 1799, in dispatch_request
    return self.view_functions[rule.endpoint](**req.view_args)
  File "/home/rancard009/Development/flask/flaskdev.py", line 95, in getResource
    jsonData = req.get(resourceProvider)
  File "/usr/lib/python3/dist-packages/requests/api.py", line 72, in get
    return request('get', url, params=params, **kwargs)
  File "/usr/lib/python3/dist-packages/requests/api.py", line 58, in request
    return session.request(method=method, url=url, **kwargs)
  File "/usr/lib/python3/dist-packages/requests/sessions.py", line 494, in request
    prep = self.prepare_request(req)
  File "/usr/lib/python3/dist-packages/requests/sessions.py", line 437, in prepare_request
    hooks=merge_hooks(request.hooks, self.hooks),
  File "/usr/lib/python3/dist-packages/requests/models.py", line 305, in prepare
    self.prepare_url(url, params)
  File "/usr/lib/python3/dist-packages/requests/models.py", line 379, in prepare_url
    raise MissingSchema(error)
requests.exceptions.MissingSchema: Invalid URL 'favicon.ico': No schema supplied. Perhaps you meant http://favicon.ico?
[2018-06-12 10:51:21,422] {/home/rancard009/.local/lib/python3.6/site-packages/flask/app.py:1761} ERROR - Exception on /configuration [GET]
Traceback (most recent call last):
  File "/home/rancard009/.local/lib/python3.6/site-packages/flask/app.py", line 2292, in wsgi_app
    response = self.full_dispatch_request()
  File "/home/rancard009/.local/lib/python3.6/site-packages/flask/app.py", line 1816, in full_dispatch_request
    return self.finalize_request(rv)
  File "/home/rancard009/.local/lib/python3.6/site-packages/flask/app.py", line 1831, in finalize_request
    response = self.make_response(rv)
  File "/home/rancard009/.local/lib/python3.6/site-packages/flask/app.py", line 1957, in make_response
    'The view function did not return a valid response. The'
TypeError: The view function did not return a valid response. The function either returned None or ended without a return statement.
[2018-06-12 10:54:23,050] {/home/rancard009/.local/lib/python3.6/site-packages/flask/app.py:1761} ERROR - Exception on /configuration [GET]
Traceback (most recent call last):
  File "/home/rancard009/.local/lib/python3.6/site-packages/flask/app.py", line 2292, in wsgi_app
    response = self.full_dispatch_request()
  File "/home/rancard009/.local/lib/python3.6/site-packages/flask/app.py", line 1816, in full_dispatch_request
    return self.finalize_request(rv)
  File "/home/rancard009/.local/lib/python3.6/site-packages/flask/app.py", line 1831, in finalize_request
    response = self.make_response(rv)
  File "/home/rancard009/.local/lib/python3.6/site-packages/flask/app.py", line 1957, in make_response
    'The view function did not return a valid response. The'
TypeError: The view function did not return a valid response. The function either returned None or ended without a return statement.
[2018-06-12 10:54:57,568] {/home/rancard009/.local/lib/python3.6/site-packages/flask/app.py:1761} ERROR - Exception on /configuration [GET]
Traceback (most recent call last):
  File "/home/rancard009/.local/lib/python3.6/site-packages/flask/app.py", line 2292, in wsgi_app
    response = self.full_dispatch_request()
  File "/home/rancard009/.local/lib/python3.6/site-packages/flask/app.py", line 1816, in full_dispatch_request
    return self.finalize_request(rv)
  File "/home/rancard009/.local/lib/python3.6/site-packages/flask/app.py", line 1831, in finalize_request
    response = self.make_response(rv)
  File "/home/rancard009/.local/lib/python3.6/site-packages/flask/app.py", line 1957, in make_response
    'The view function did not return a valid response. The'
TypeError: The view function did not return a valid response. The function either returned None or ended without a return statement.
[2018-06-12 10:55:19,999] {/home/rancard009/.local/lib/python3.6/site-packages/flask/app.py:1761} ERROR - Exception on /configuration [GET]
Traceback (most recent call last):
  File "/home/rancard009/.local/lib/python3.6/site-packages/flask/app.py", line 2292, in wsgi_app
    response = self.full_dispatch_request()
  File "/home/rancard009/.local/lib/python3.6/site-packages/flask/app.py", line 1816, in full_dispatch_request
    return self.finalize_request(rv)
  File "/home/rancard009/.local/lib/python3.6/site-packages/flask/app.py", line 1831, in finalize_request
    response = self.make_response(rv)
  File "/home/rancard009/.local/lib/python3.6/site-packages/flask/app.py", line 1957, in make_response
    'The view function did not return a valid response. The'
TypeError: The view function did not return a valid response. The function either returned None or ended without a return statement.
[2018-06-12 11:03:14,504] {/home/rancard009/.local/lib/python3.6/site-packages/flask/app.py:1761} ERROR - Exception on /configuration [GET]
Traceback (most recent call last):
  File "/home/rancard009/.local/lib/python3.6/site-packages/flask/app.py", line 2292, in wsgi_app
    response = self.full_dispatch_request()
  File "/home/rancard009/.local/lib/python3.6/site-packages/flask/app.py", line 1816, in full_dispatch_request
    return self.finalize_request(rv)
  File "/home/rancard009/.local/lib/python3.6/site-packages/flask/app.py", line 1831, in finalize_request
    response = self.make_response(rv)
  File "/home/rancard009/.local/lib/python3.6/site-packages/flask/app.py", line 1957, in make_response
    'The view function did not return a valid response. The'
TypeError: The view function did not return a valid response. The function either returned None or ended without a return statement.
[2018-06-12 11:05:18,965] {/home/rancard009/.local/lib/python3.6/site-packages/flask/app.py:1761} ERROR - Exception on /configuration [GET]
Traceback (most recent call last):
  File "/home/rancard009/.local/lib/python3.6/site-packages/flask/app.py", line 2292, in wsgi_app
    response = self.full_dispatch_request()
  File "/home/rancard009/.local/lib/python3.6/site-packages/flask/app.py", line 1816, in full_dispatch_request
    return self.finalize_request(rv)
  File "/home/rancard009/.local/lib/python3.6/site-packages/flask/app.py", line 1831, in finalize_request
    response = self.make_response(rv)
  File "/home/rancard009/.local/lib/python3.6/site-packages/flask/app.py", line 1957, in make_response
    'The view function did not return a valid response. The'
TypeError: The view function did not return a valid response. The function either returned None or ended without a return statement.
[2018-06-12 11:07:44,935] {/home/rancard009/.local/lib/python3.6/site-packages/flask/app.py:1761} ERROR - Exception on /configuration [GET]
Traceback (most recent call last):
  File "/home/rancard009/.local/lib/python3.6/site-packages/flask/app.py", line 2292, in wsgi_app
    response = self.full_dispatch_request()
  File "/home/rancard009/.local/lib/python3.6/site-packages/flask/app.py", line 1816, in full_dispatch_request
    return self.finalize_request(rv)
  File "/home/rancard009/.local/lib/python3.6/site-packages/flask/app.py", line 1831, in finalize_request
    response = self.make_response(rv)
  File "/home/rancard009/.local/lib/python3.6/site-packages/flask/app.py", line 1957, in make_response
    'The view function did not return a valid response. The'
TypeError: The view function did not return a valid response. The function either returned None or ended without a return statement.
[2018-06-12 11:10:25,856] {/home/rancard009/.local/lib/python3.6/site-packages/flask/app.py:1761} ERROR - Exception on /configuration [GET]
Traceback (most recent call last):
  File "/home/rancard009/.local/lib/python3.6/site-packages/flask/app.py", line 1974, in make_response
    rv = self.response_class.force_type(rv, request.environ)
  File "/home/rancard009/.local/lib/python3.6/site-packages/werkzeug/wrappers.py", line 921, in force_type
    response = BaseResponse(*_run_wsgi_app(response, environ))
  File "/home/rancard009/.local/lib/python3.6/site-packages/werkzeug/wrappers.py", line 59, in _run_wsgi_app
    return _run_wsgi_app(*args)
  File "/home/rancard009/.local/lib/python3.6/site-packages/werkzeug/test.py", line 923, in run_wsgi_app
    app_rv = app(environ, start_response)
TypeError: 'bool' object is not callable

During handling of the above exception, another exception occurred:

Traceback (most recent call last):
  File "/home/rancard009/.local/lib/python3.6/site-packages/flask/app.py", line 2292, in wsgi_app
    response = self.full_dispatch_request()
  File "/home/rancard009/.local/lib/python3.6/site-packages/flask/app.py", line 1816, in full_dispatch_request
    return self.finalize_request(rv)
  File "/home/rancard009/.local/lib/python3.6/site-packages/flask/app.py", line 1831, in finalize_request
    response = self.make_response(rv)
  File "/home/rancard009/.local/lib/python3.6/site-packages/flask/app.py", line 1982, in make_response
    reraise(TypeError, new_error, sys.exc_info()[2])
  File "/home/rancard009/.local/lib/python3.6/site-packages/flask/_compat.py", line 34, in reraise
    raise value.with_traceback(tb)
  File "/home/rancard009/.local/lib/python3.6/site-packages/flask/app.py", line 1974, in make_response
    rv = self.response_class.force_type(rv, request.environ)
  File "/home/rancard009/.local/lib/python3.6/site-packages/werkzeug/wrappers.py", line 921, in force_type
    response = BaseResponse(*_run_wsgi_app(response, environ))
  File "/home/rancard009/.local/lib/python3.6/site-packages/werkzeug/wrappers.py", line 59, in _run_wsgi_app
    return _run_wsgi_app(*args)
  File "/home/rancard009/.local/lib/python3.6/site-packages/werkzeug/test.py", line 923, in run_wsgi_app
    app_rv = app(environ, start_response)
TypeError: 'bool' object is not callable
The view function did not return a valid response. The return type must be a string, tuple, Response instance, or WSGI callable, but it was a bool.
[2018-06-12 11:48:42,973] {/home/rancard009/.local/lib/python3.6/site-packages/flask/app.py:1761} ERROR - Exception on /configuration [GET]
Traceback (most recent call last):
  File "/home/rancard009/.local/lib/python3.6/site-packages/flask/app.py", line 1974, in make_response
    rv = self.response_class.force_type(rv, request.environ)
  File "/home/rancard009/.local/lib/python3.6/site-packages/werkzeug/wrappers.py", line 921, in force_type
    response = BaseResponse(*_run_wsgi_app(response, environ))
  File "/home/rancard009/.local/lib/python3.6/site-packages/werkzeug/wrappers.py", line 59, in _run_wsgi_app
    return _run_wsgi_app(*args)
  File "/home/rancard009/.local/lib/python3.6/site-packages/werkzeug/test.py", line 923, in run_wsgi_app
    app_rv = app(environ, start_response)
TypeError: 'list' object is not callable

During handling of the above exception, another exception occurred:

Traceback (most recent call last):
  File "/home/rancard009/.local/lib/python3.6/site-packages/flask/app.py", line 2292, in wsgi_app
    response = self.full_dispatch_request()
  File "/home/rancard009/.local/lib/python3.6/site-packages/flask/app.py", line 1816, in full_dispatch_request
    return self.finalize_request(rv)
  File "/home/rancard009/.local/lib/python3.6/site-packages/flask/app.py", line 1831, in finalize_request
    response = self.make_response(rv)
  File "/home/rancard009/.local/lib/python3.6/site-packages/flask/app.py", line 1982, in make_response
    reraise(TypeError, new_error, sys.exc_info()[2])
  File "/home/rancard009/.local/lib/python3.6/site-packages/flask/_compat.py", line 34, in reraise
    raise value.with_traceback(tb)
  File "/home/rancard009/.local/lib/python3.6/site-packages/flask/app.py", line 1974, in make_response
    rv = self.response_class.force_type(rv, request.environ)
  File "/home/rancard009/.local/lib/python3.6/site-packages/werkzeug/wrappers.py", line 921, in force_type
    response = BaseResponse(*_run_wsgi_app(response, environ))
  File "/home/rancard009/.local/lib/python3.6/site-packages/werkzeug/wrappers.py", line 59, in _run_wsgi_app
    return _run_wsgi_app(*args)
  File "/home/rancard009/.local/lib/python3.6/site-packages/werkzeug/test.py", line 923, in run_wsgi_app
    app_rv = app(environ, start_response)
TypeError: 'list' object is not callable
The view function did not return a valid response. The return type must be a string, tuple, Response instance, or WSGI callable, but it was a list.
